<?xml version="1.0"?>

<robot name="ros_robot">
  <material name="black">
    <color rgba="0 0 0 1.0"/>
  </material>
  <material name="darkgray">
    <color rgba="0.3 0.3 0.3 1.0"/>
  </material>
  <material name="lightgray">
    <color rgba="0.8 0.8 0.8 1.0"/>
  </material>
  <material name="white">
    <color rgba="1.0 1.0 1.0 1.0"/>
  </material>
  
  <link name="base_footprint"/>

  <link name="base_link">
    <visual>
      <geometry>
        <!-- Dimension of body -->
        <box size="0.25 0.12 0.10"/>
      </geometry>
      <material name="lightgray"/>
    </visual>
  </link>

  <joint name="base_joint" type="fixed">
    <parent link="base_footprint"/>
    <child link="base_link"/>
    <!-- Placement of body 0.0279 m (radius of wheel) + 0.1 m / 2 (center of body) -->
    <origin xyz="0 0 0.0779" rpy="0 0 0"/>
  </joint>

  <link name="laser_frame">
    <visual>
      <geometry>
        <!-- Dimension of rplidar a2 -->
        <cylinder length="0.041" radius="0.038"/>
      </geometry>
      <material name="darkgray"/>
    </visual>
  </link>

  <joint name="laser_joint" type="fixed">
    <parent link="base_link"/>
    <child link="laser_frame"/>
    <!-- Dimension of body -->
    <origin xyz="0 0 0.06" rpy="0 0 0"/>
  </joint>

  <link name="r_wheel_frame">
    <visual>
      <geometry>
        <cylinder length="0.025" radius="0.028"/>
      </geometry>
      <material name="black"/>
    </visual>
  </link>

  <joint name="r_wheel_joint" type="continuous">
    <parent link="base_link"/>
    <child link="r_wheel_frame"/>
    <origin xyz="0 -0.0625 -0.05" rpy="1.5707963268 0 0" />
    <axis xyz="0 0 1" />
  </joint>

  <link name="l_wheel_frame">
    <visual>
      <geometry>
        <cylinder length="0.025" radius="0.028"/>
      </geometry>
      <material name="black"/>
    </visual>
  </link>

  <joint name="l_wheel_joint" type="continuous">
    <parent link="base_link"/>
    <child link="l_wheel_frame"/>
    <!-- 0.1 / 2 -->
    <origin xyz="0 0.0625 -0.05" rpy="1.5707963268 0 0" />
    <axis xyz="0 0 1" />
  </joint>
<!--
  <link name="color_link">
    <visual>
      <geometry>
        <box length="0.02 0.02 0.045"/>
      </geometry>
      <material name="lightgray"/>
    </visual>
  </link>

  <joint name="color_joint" type="fixed">
    <parent link="base_link"/>
    <child link="color_link"/>
    <origin xyz="-0.0 0.0240000007629 0.0002" rpy="1.57079632679 -0.0 -1.57079632679" />
    <axis xyz="0 0 0" />
  </joint>

  <link name="ultasonic_link">
    <visual>
      <geometry>
        <box length="0.045 0.05 0.02"/>
      </geometry>
      <material name="lightgray"/>
    </visual>
  </link>

  <joint name="ultrasonic_joint" type="fixed">
    <parent link="base_link"/>
    <child link="ultrsonic_link"/>
    <origin xyz="-0.0 0.0240000007629 0.0002" rpy="1.57079632679 -0.0 -1.57079632679" />
    <axis xyz="0 0 0" />
  </joint>
  -->
</robot>

<!-- 0.7853981634 1.5707963268 3.1415926536 -->

